Workbook

Sheet Meta
B2: Supplementary Data for "Democratising climate change mitigation pathways using modernised stabilisation wedges"
C4: Nathan Johnson and Iain Staffell
C5: 25 July 2025 –– Version 1
C6: Citation: ADD DOI ONCE KNOWN
C7: License: Creative Commons CC BY 4.0
C9: This workbook contains the raw data behind Figures 1 to 4 of the main paper
B13: Fig1: Historical global GHG emissions and a spectrum of stylised future pathways to 2050, showing the relationship between the number of wedges deployed and global temperature outcomes.
C15: Number of Wedges | J15: The number of wedges deployed, relative to our No Policy baseline. The three example pathways in the paper correspond to 0 (No Policy), 17 (Current Policies), and 37 (Decarbonisation).
C16: Emissions in 2020 | J16: Global net greenhouse gas emissions (GtCO₂e). Stylised emissions in 2020, calculated as the mean of 2019 and 2021.
C17: Emissions in 2050 | J17: Global net greenhouse gas emissions (GtCO₂e). Emissions in 2050.
C18: Cumulative Emissions (2020–50) | J18: Global net greenhouse gas emissions (GtCO₂e). Cumulative emissions over the 30 years 2020 to 2050.
C19: 2050 P33 Temperature | J19: Global temperature rise (°C). Calculated from cumulative emissions, aggregating the 33rd percentile of the warming temperature (GSAT) in 2050 from AR6 scenarios using MAGICC.
C20: 2050 P50 Temperature | J20: Global temperature rise (°C). Calculated from cumulative emissions, aggregating the median of the warming temperature (GSAT) in 2050 from AR6 scenarios using MAGICC.
C21: 2050 P67 Temperature | J21: Global temperature rise (°C). Calculated from cumulative emissions, aggregating the 67th percentile of the warming temperature (GSAT) in 2050 from AR6 scenarios using MAGICC.
C22: 2100 P33 Temperature | J22: Global temperature rise (°C). Calculated from cumulative emissions, aggregating the 33rd percentile of the warming temperature (GSAT) in 2100 from AR6 scenarios using MAGICC.
C23: 2100 P50 Temperature | J23: Global temperature rise (°C). Calculated from cumulative emissions, aggregating the median of the warming temperature (GSAT) in 2100 from AR6 scenarios using MAGICC.
C24: 2100 P67 Temperature | J24: Global temperature rise (°C). Calculated from cumulative emissions, aggregating the 67th percentile of the warming temperature (GSAT) in 2100 from AR6 scenarios using MAGICC.
B28: Fig2Fig3: The 36 mitigation strategies which have the potential to achieve at least one wedge of mitigation, and the scale of deployment required for each
C30: Sector | J30: Which sector the result relates to.
C31: Strategy | J31: Which strategy the result relates to.
C32: Unit | J32: The unit for evaluating effort required for a wedge (wedge target columns) and current uptake (current value column).
C33: Current value | J33: Status of this strategy at present (the yellow circles in Fig. 3). This represents various years depending on data availability, typically 2020 to 2024.
C34: Current share | J34: Status of this strategy at present, relative to the global market.
C35: Source | J35: Source used for current value (see Fig2Fig3Context for definitions).
C36: Wedge target | J36: Central estimate for the additional effort required to achieve a wedge (the bars in Fig. 3).
C37: Wedge target (high) | J37: Upper estimate for the additional effort required to achieve a wedge.
C38: Wedge target (low) | J38: Lower estimate for the additional effort required to achieve a wedge.
C39: Wedge share | J39: Central estimate for the global share of activity required to achieve a wedge (as stated in Fig. 2).
C40: Wedge share (high) | J40: Upper estimate for the global share of activity required to achieve a wedge.
C41: Wedge share (low) | J41: Lower estimate for the global share of activity required to achieve a wedge.
C42: Scenario analysis: Wedge target (IEA6DS) | N42: For strategies evaluated using the Global Calculator, the effort required to achieve a wedge within the IEA6DS scenario.
C43: Scenario analysis: Wedge target (IEA4DS) | N43: For strategies evaluated using the Global Calculator, the effort required to achieve a wedge within the IEA4DS scenario.
C44: Scenario analysis: Wedge target (RCP8.5) | N44: For strategies evaluated using the Global Calculator, the effort required to achieve a wedge within the RCP8.5 scenario.
C45: Scenario analysis: Wedge target (RCP6.0) | N45: For strategies evaluated using the Global Calculator, the effort required to achieve a wedge within the RCP6.0 scenario.
C46: Scenario analysis: Wedge share (IEA6DS) | N46: For strategies evaluated using the Global Calculator, the global share of activity required to achieve a wedge within the IEA6DS scenario.
C47: Scenario analysis: Wedge share (IEA4DS) | N47: For strategies evaluated using the Global Calculator, the effort required to achieve a wedge within the IEA4DS scenario.
C48: Scenario analysis: Wedge share (RCP8.5) | N48: For strategies evaluated using the Global Calculator, the effort required to achieve a wedge within the RCP8.5 scenario.
C49: Scenario analysis: Wedge share (RCP6.0) | N49: For strategies evaluated using the Global Calculator, the effort required to achieve a wedge within the RCP6.0 scenario.
C50: Scenario independent: Wedge target (central) | N50: For strategies that are scenario indepdenent, the central estimate of effort required to achieve a wedge.
C51: Scenario independent: Wedge target (high) | N51: For strategies that are scenario indepdenent, the upper estimate of effort required to achieve a wedge.
...

Sheet Fig1
A1: Number of Wedges | B1: Emissions in 2020 | C1: Emissions in 2050 | D1: Cumulative Emissions (2020–50) | E1: 2050 P33 Temperature | F1: 2050 P50 Temperature | G1: 2050 P67 Temperature | H1: 2100 P33 Temperature | I1: 2100 P50 Temperature | J1: 2100 P67 Temperature
A2: 0 | B2: 54.707258 | C2: 83.784365 | D2: =B2 + AVERAGE(B2:C2) * 30 -> 2132.0816 | E2: 2.0001288 | F2: 2.1360278 | G2: 2.2856898 | H2: 3.4245582 | I2: 3.7258512 | J2: 4.0514634
A3: 1 | B3: 54.707258 | C3: =C2 - 2 -> 81.784365 | D3: =B3 + AVERAGE(B3:C3) * 30 -> 2102.0816 | E3: 1.984427 | F3: 2.1196493 | G3: 2.267229 | H3: 3.378548 | I3: 3.6751906 | J3: 3.9951027
A4: 2 | B4: 54.707258 | C4: =C3 - 2 -> 79.784365 | D4: =B4 + AVERAGE(B4:C4) * 30 -> 2072.0816 | E4: 1.9694209 | F4: 2.103946 | G4: 2.2496977 | H4: 3.329909 | I4: 3.6219309 | J4: 3.9361527
A5: 3 | B5: 54.707258 | C5: =C4 - 2 -> 77.784365 | D5: =B5 + AVERAGE(B5:C5) * 30 -> 2042.0816 | E5: 1.9552445 | F5: 2.0890767 | G5: 2.2333141 | H5: 3.2779892 | I5: 3.5654117 | J5: 3.8739548
A6: 4 | B6: 54.707258 | C6: =C5 - 2 -> 75.784365 | D6: =B6 + AVERAGE(B6:C6) * 30 -> 2012.0816 | E6: 1.9419419 | F6: 2.0751136 | G6: 2.2181812 | H6: 3.2222928 | I6: 3.5051298 | J6: 3.8080101
A7: 5 | B7: 54.707258 | C7: =C6 - 2 -> 73.784365 | D7: =B7 + AVERAGE(B7:C7) * 30 -> 1982.0816 | E7: 1.9294657 | F7: 2.0620381 | G7: 2.2042813 | H7: 3.1625236 | I7: 3.4407828 | J7: 3.7380219
A8: 6 | B8: 54.707258 | C8: =C7 - 2 -> 71.784365 | D8: =B8 + AVERAGE(B8:C8) * 30 -> 1952.0816 | E8: 1.9176915 | F8: 2.0497538 | G8: 2.1914913 | H8: 3.0985861 | I8: 3.3722697 | J8: 3.6638964
A9: 7 | B9: 54.707258 | C9: =C8 - 2 -> 69.784365 | D9: =B9 + AVERAGE(B9:C9) * 30 -> 1922.0816 | E9: 1.9064349 | F9: 2.0380995 | G9: 2.1796003 | H9: 3.0306006 | I9: 3.299706 | J9: 3.5857566
A10: 8 | B10: 54.707258 | C10: =C9 - 2 -> 67.784365 | D10: =B10 + AVERAGE(B10:C10) * 30 -> 1892.0816 | E10: 1.8954724 | F10: 2.0268685 | G10: 2.1683338 | H10: 2.9588933 | I10: 3.2234136 | J10: 3.5039306
A11: 9 | B11: 54.707258 | C11: =C10 - 2 -> 65.784365 | D11: =B11 + AVERAGE(B11:C11) * 30 -> 1862.0816 | E11: 1.8845696 | F11: 2.0158373 | G11: 2.1573928 | H11: 2.8839215 | I11: 3.143846 | J11: 3.4188771
A12: 10 | B12: 54.707258 | C12: =C11 - 2 -> 63.784365 | D12: =B12 + AVERAGE(B12:C12) * 30 -> 1832.0816 | E12: 1.8735067 | F12: 2.0047909 | G12: 2.1464873 | H12: 2.8062181 | I12: 3.0615316 | J12: 3.331128
A13: 11 | B13: 54.707258 | C13: =C12 - 2 -> 61.784365 | D13: =B13 + AVERAGE(B13:C13) * 30 -> 1802.0816 | E13: 1.8621181 | F13: 1.9935559 | G13: 2.1353788 | H13: 2.7264194 | I13: 2.9771021 | J13: 3.2413153
A14: 12 | B14: 54.707258 | C14: =C13 - 2 -> 59.784365 | D14: =B14 + AVERAGE(B14:C14) * 30 -> 1772.0816 | E14: 1.8503227 | F14: 1.9820285 | G14: 2.1239168 | H14: 2.645234 | I14: 2.8912612 | J14: 3.1501387
... A52: 50 | B52: 54.707258 | C52: =C51 - 2 -> -16.215635 | D52: =B52 + AVERAGE(B52:C52) * 30 -> 632.0816 | E52: 1.3701692 | F52: 1.4855403 | G52: 1.6042917 | H52: 1.172508 | I52: 1.312078 | J52: 1.4542532

Sheet Fig2Fig3
A1: Sector | B1: Strategy | C1: Unit | D1: Current value | E1: Current share | F1: Source | G1: Wedge target | H1: Wedge target (high) | I1: Wedge target (low) | J1: Wedge share | K1: Wedge share (high) | L1: Wedge share (low) | M1: Scenario analysis: Wedge target (IEA6DS) | N1: Scenario analysis: Wedge target (IEA4DS) | O1: Scenario analysis: Wedge target (RCP8.5) | P1: Scenario analysis: Wedge target (RCP6.0) | Q1: Scenario analysis: Wedge share (IEA6DS) | R1: Scenario analysis: Wedge share (IEA4DS) | S1: Scenario analysis: Wedge share (RCP8.5) | T1: Scenario analysis: Wedge share (RCP6.0) | U1: Scenario independent: Wedge target (central) | V1: Scenario independent: Wedge target (high) | W1: Scenario independent: Wedge target (low)
A2: Power | B2: Power BECCS with crops | C2: TWh (output) | D2: 0 | E2: =D2/Fig2Fig3Context!$F$6 -> 0 | F2: Negligible | G2: =AVERAGE(M2:P2) -> 1957.0388 | H2: =MAX(M2:P2) -> 2061.369 | I2: =MIN(M2:P2) -> 1812.255 | J2: =AVERAGE(Q2:T2) -> 0.045478124 | K2: =MAX(Q2:T2) -> 0.059913562 | L2: =MIN(Q2:T2) -> 0.02941139 | M2: 1957.048 | N2: 1997.483 | O2: 1812.255 | P2: 2061.369 | Q2: =M2/Fig2Fig3Context!F$41 -> 0.044646882 | R2: =N2/Fig2Fig3Context!G$41 -> 0.047940663 | S2: =O2/Fig2Fig3Context!H$41 -> 0.02941139 | T2: =P2/Fig2Fig3Context!I$41 -> 0.059913562 | U2: –– | V2: –– | W2: ––
A3: Power | B3: Power BECCS with waste | C3: TWh (output) | D3: 0 | E3: =D3/Fig2Fig3Context!$F$6 -> 0 | F3: Negligible | G3: =AVERAGE(M3:P3) -> 1573.4222 | H3: =MAX(M3:P3) -> 1640.754 | I3: =MIN(M3:P3) -> 1478.94 | J3: =AVERAGE(Q3:T3) -> 0.036499852 | K3: =MAX(Q3:T3) -> 0.047688413 | L3: =MIN(Q3:T3) -> 0.024001965 | M3: 1573.973 | N3: 1600.022 | O3: 1478.94 | P3: 1640.754 | Q3: =M3/Fig2Fig3Context!F$41 -> 0.035907646 | R3: =N3/Fig2Fig3Context!G$41 -> 0.038401386 | S3: =O3/Fig2Fig3Context!H$41 -> 0.024001965 | T3: =P3/Fig2Fig3Context!I$41 -> 0.047688413 | U3: –– | V3: –– | W3: ––
A4: Power | B4: Retrofit coal plants with CCS | C4: TWh (output) | D4: 0 | E4: =D4/Fig2Fig3Context!$F$6 -> 0 | F4: Negligible | G4: =AVERAGE(M4:P4) -> 2867.1449 | H4: =MAX(M4:P4) -> 2892.9206 | I4: =MIN(M4:P4) -> 2858.553 | J4: =AVERAGE(Q4:T4) -> 0.065963355 | K4: =MAX(Q4:T4) -> 0.083083665 | L4: =MIN(Q4:T4) -> 0.046949694 | M4: 2858.553 | N4: 2858.553 | O4: 2892.9206 | P4: 2858.553 | Q4: =M4/Fig2Fig3Context!F$41 -> 0.065213259 | R4: =N4/Fig2Fig3Context!G$41 -> 0.068606804 | S4: =O4/Fig2Fig3Context!H$41 -> 0.046949694 | T4: =P4/Fig2Fig3Context!I$41 -> 0.083083665 | U4: –– | V4: –– | W4: ––
A5: Power | B5: Install more wind farms | C5: TWh (output) | D5: 2503.88 | E5: =D5/Fig2Fig3Context!$F$6 -> 0.080992844 | F5: 1 | G5: =AVERAGE(M5:P5) -> 2836.0816 | H5: =MAX(M5:P5) -> 3055.9501 | I5: =MIN(M5:P5) -> 2538.621 | J5: =AVERAGE(Q5:T5) -> 0.066163931 | K5: =MAX(Q5:T5) -> 0.088821 | L5: =MIN(Q5:T5) -> 0.041199706 | M5: 2832.1424 | N5: 2917.6129 | O5: 2538.621 | P5: 3055.9501 | Q5: =M5/Fig2Fig3Context!F$41 -> 0.064610744 | R5: =N5/Fig2Fig3Context!G$41 -> 0.070024274 | S5: =O5/Fig2Fig3Context!H$41 -> 0.041199706 | T5: =P5/Fig2Fig3Context!I$41 -> 0.088821 | U5: –– | V5: –– | W5: ––
A6: Power | B6: Install more solar panels | C6: TWh (output) | D6: 2129.12 | E6: =D6/Fig2Fig3Context!$F$6 -> 0.068870506 | F6: 1 | G6: =AVERAGE(M6:P6) -> 2836.0816 | H6: =MAX(M6:P6) -> 3055.9501 | I6: =MIN(M6:P6) -> 2538.621 | J6: =AVERAGE(Q6:T6) -> 0.066163931 | K6: =MAX(Q6:T6) -> 0.088821 | L6: =MIN(Q6:T6) -> 0.041199706 | M6: 2832.1424 | N6: 2917.6129 | O6: 2538.621 | P6: 3055.9501 | Q6: =M6/Fig2Fig3Context!F$41 -> 0.064610744 | R6: =N6/Fig2Fig3Context!G$41 -> 0.070024274 | S6: =O6/Fig2Fig3Context!H$41 -> 0.041199706 | T6: =P6/Fig2Fig3Context!I$41 -> 0.088821 | U6: –– | V6: –– | W6: ––
A7: Power | B7: Install more nuclear reactors | C7: TWh (output) | D7: 2777.65 | E7: =D7/Fig2Fig3Context!$F$6 -> 0.089848464 | F7: 1 | G7: =AVERAGE(M7:P7) -> 2836.0816 | H7: =MAX(M7:P7) -> 3055.9501 | I7: =MIN(M7:P7) -> 2538.621 | J7: =AVERAGE(Q7:T7) -> 0.066163931 | K7: =MAX(Q7:T7) -> 0.088821 | L7: =MIN(Q7:T7) -> 0.041199706 | M7: 2832.1424 | N7: 2917.6129 | O7: 2538.621 | P7: 3055.9501 | Q7: =M7/Fig2Fig3Context!F$41 -> 0.064610744 | R7: =N7/Fig2Fig3Context!G$41 -> 0.070024274 | S7: =O7/Fig2Fig3Context!H$41 -> 0.041199706 | T7: =P7/Fig2Fig3Context!I$41 -> 0.088821 | U7: –– | V7: –– | W7: ––
A8: Power | B8: Switch from coal to gas plants | C8: TWh (output)* | D8: 6891.22 | E8: =D8/Fig2Fig3Context!$F$6 -> 0.22290985 | F8: 1 | G8: =AVERAGE(M8:P8) -> 4117.1617 | H8: =MAX(M8:P8) -> 4153.3085 | I8: =MIN(M8:P8) -> 4105.1128 | J8: =AVERAGE(Q8:T8) -> 0.094724 | K8: =MAX(Q8:T8) -> 0.11931485 | L8: =MIN(Q8:T8) -> 0.06740474 | M8: 4105.1128 | N8: 4105.1128 | O8: 4153.3085 | P8: 4105.1128 | Q8: =M8/Fig2Fig3Context!F$41 -> 0.093651504 | R8: =N8/Fig2Fig3Context!G$41 -> 0.098524908 | S8: =O8/Fig2Fig3Context!H$41 -> 0.06740474 | T8: =P8/Fig2Fig3Context!I$41 -> 0.11931485 | U8: –– | V8: –– | W8: ––
A9: Power | B9: Retrofit gas plants with CCS | C9: TWh (output) | D9: 0 | E9: =D9/Fig2Fig3Context!$F$6 -> 0 | F9: Negligible | G9: =AVERAGE(M9:P9) -> 7079.9995 | H9: =MAX(M9:P9) -> 7157.537 | I9: =MIN(M9:P9) -> 7054.1536 | J9: =AVERAGE(Q9:T9) -> 0.16285549 | K9: =MAX(Q9:T9) -> 0.20502854 | L9: =MIN(Q9:T9) -> 0.11616087 | M9: 7054.1536 | N9: 7054.1536 | O9: 7157.537 | P9: 7054.1536 | Q9: =M9/Fig2Fig3Context!F$41 -> 0.1609291 | R9: =N9/Fig2Fig3Context!G$41 -> 0.16930347 | S9: =O9/Fig2Fig3Context!H$41 -> 0.11616087 | T9: =P9/Fig2Fig3Context!I$41 -> 0.20502854 | U9: –– | V9: –– | W9: ––
A10: Transport | B10: Avoid car travel or walk/cycle | C10: Trillion p-km | D10: 8.3505 | E10: =D10/Fig2Fig3Context!$F$8 -> 0.12017536 | F10: 3 | G10: =AVERAGE(M10:P10) -> 18.681767 | H10: =MAX(M10:P10) -> 19.76079 | I10: =MIN(M10:P10) -> 17.42949 | J10: =AVERAGE(Q10:T10) -> 0.16947323 | K10: =MAX(Q10:T10) -> 0.18863245 | L10: =MIN(Q10:T10) -> 0.14140586 | M10: 18.89259 | N10: 19.76079 | O10: 17.42949 | P10: 18.6442 | Q10: =M10/Fig2Fig3Context!F$42 -> 0.18034479 | R10: =N10/Fig2Fig3Context!G$42 -> 0.18863245 | S10: =O10/Fig2Fig3Context!H$42 -> 0.14140586 | T10: =P10/Fig2Fig3Context!I$42 -> 0.16750984 | U10: –– | V10: –– | W10: ––
A11: Transport | B11: Deploy more electric vehicles | C11: Trillion p-km | D11: =58000000*1.65*14825/1000000000000 -> 1.4187525 | E11: =D11/Fig2Fig3Context!$F$8 -> 0.02041783 | F11: 10 | G11: =AVERAGE(M11:P11) -> 19.010425 | H11: =MAX(M11:P11) -> 20.12813 | I11: =MIN(M11:P11) -> 17.71464 | J11: =AVERAGE(Q11:T11) -> 0.17246256 | K11: =MAX(Q11:T11) -> 0.192139 | L11: =MIN(Q11:T11) -> 0.14371929 | M11: 19.22808 | N11: 20.12813 | O11: 17.71464 | P11: 18.97085 | Q11: =M11/Fig2Fig3Context!F$42 -> 0.18354731 | R11: =N11/Fig2Fig3Context!G$42 -> 0.192139 | S11: =O11/Fig2Fig3Context!H$42 -> 0.14371929 | T11: =P11/Fig2Fig3Context!I$42 -> 0.17044464 | U11: –– | V11: –– | W11: ––
A12: Transport | B12: Deploy more biofuels | C12: Trillion p-km | D12: =0.1057 * 5.86 / 0.664 * 1.65 -> 1.5391767 | E12: =D12/Fig2Fig3Context!$F$8 -> 0.022150901 | F12: 11 | G12: =AVERAGE(M12:P12) -> 19.9948 | H12: =MAX(M12:P12) -> 21.15226 | I12: =MIN(M12:P12) -> 18.65372 | J12: =AVERAGE(Q12:T12) -> 0.1813847 | K12: =MAX(Q12:T12) -> 0.20191513 | L12: =MIN(Q12:T12) -> 0.15133807 | M12: 20.2179 | N12: 21.15226 | O12: 18.65372 | P12: 19.95532 | Q12: =M12/Fig2Fig3Context!F$42 -> 0.19299592 | R12: =N12/Fig2Fig3Context!G$42 -> 0.20191513 | S12: =O12/Fig2Fig3Context!H$42 -> 0.15133807 | T12: =P12/Fig2Fig3Context!I$42 -> 0.17928967 | U12: –– | V12: –– | W12: ––
A13: Transport | B13: Use more public transport | C13: Trillion p-km | D13: 22.394838 | E13: =D13/Fig2Fig3Context!$F$8 -> 0.322293 | F13: 3 | G13: =AVERAGE(M13:P13) -> 21.327185 | H13: =MAX(M13:P13) -> 22.73727 | I13: =MIN(M13:P13) -> 19.70466 | J13: =AVERAGE(Q13:T13) -> 0.19354227 | K13: =MAX(Q13:T13) -> 0.21704531 | L13: =MIN(Q13:T13) -> 0.15986437 | M13: 21.59537 | N13: 22.73727 | O13: 19.70466 | P13: 21.27144 | Q13: =M13/Fig2Fig3Context!F$42 -> 0.20614497 | R13: =N13/Fig2Fig3Context!G$42 -> 0.21704531 | S13: =O13/Fig2Fig3Context!H$42 -> 0.15986437 | T13: =P13/Fig2Fig3Context!I$42 -> 0.19111442 | U13: –– | V13: –– | W13: ––
A14: Transport | B14: Decarbonise surface freight | C14: GtCO2e | D14: 4.1939755 | E14: –– | F14: 3 | G14: =AVERAGE(M14:P14) -> -2 | H14: =MAX(M14:P14) -> -2 | I14: =MIN(M14:P14) -> -2 | J14: =AVERAGE(Q14:T14) -> -0.36152697 | K14: =MAX(Q14:T14) -> -0.28544254 | L14: =MIN(Q14:T14) -> -0.43478573 | M14: -2 | N14: -2 | O14: -2 | P14: -2 | Q14: =M14/Fig2Fig3Context!F$48 -> -0.38104332 | R14: =N14/Fig2Fig3Context!G$48 -> -0.43478573 | S14: =O14/Fig2Fig3Context!H$48 -> -0.28544254 | T14: =P14/Fig2Fig3Context!I$48 -> -0.34483627 | U14: –– | V14: –– | W14: ––
A15: Transport | B15: Avoid taking flights | C15: Trillion p-km | D15: 7.038077 | E15: –– | F15: 3 | G15: =AVERAGE(M15:P15) -> -10.529271 | H15: =MAX(M15:P15) -> -9.633295 | I15: =MIN(M15:P15) -> -11.2855 | J15: =AVERAGE(Q15:T15) -> -0.70303821 | K15: =MAX(Q15:T15) -> -0.37194189 | L15: =MIN(Q15:T15) -> -0.97121343 | M15: -10.774 | N15: -11.2855 | O15: -9.633295 | P15: -10.42429 | Q15: =M15/Fig2Fig3Context!F$43 -> -0.92719449 | R15: =N15/Fig2Fig3Context!G$43 -> -0.97121343 | S15: =O15/Fig2Fig3Context!H$43 -> -0.37194189 | T15: =P15/Fig2Fig3Context!I$43 -> -0.54180301 | U15: –– | V15: –– | W15: ––
A16: Transport | B16: Improve efficiency of cars | C16: l/100km | D16: =0.664/8.9*100 -> 7.4606742 | E16: –– | F16: 3 | G16: =AVERAGE(M16:P16) -> 3.722359 | H16: =MAX(M16:P16) -> 4.456696 | I16: =MIN(M16:P16) -> 3.130831 | J16: =AVERAGE(Q16:T16) -> -0.50106935 | K16: =MAX(Q16:T16) -> -0.40264165 | L16: =MIN(Q16:T16) -> -0.58035548 | M16: 3.408867 | N16: 3.130831 | O16: 4.456696 | P16: 3.893042 | Q16: =(M16/$D16)-1 -> -0.54308861 | R16: =(N16/$D16)-1 -> -0.58035548 | S16: =(O16/$D16)-1 -> -0.40264165 | T16: =(P16/$D16)-1 -> -0.47819166 | U16: –– | V16: –– | W16: ––
A17: Transport | B17: Reduce building heat transfer | C17: W/m2*K | D17: 1.508 | E17: –– | F17: 3 | G17: =AVERAGE(M17:P17) -> 0.75069753 | H17: =MAX(M17:P17) -> 0.8905009 | I17: =MIN(M17:P17) -> 0.5880099 | J17: =AVERAGE(Q17:T17) -> -0.50218996 | K17: =MAX(Q17:T17) -> -0.40948216 | L17: =MIN(Q17:T17) -> -0.61007301 | M17: 0.7735818 | N17: 0.5880099 | O17: 0.8905009 | P17: –– | Q17: =(M17/$D17)-1 -> -0.48701472 | R17: =(N17/$D17)-1 -> -0.61007301 | S17: =(O17/$D17)-1 -> -0.40948216 | T17: –– | U17: –– | V17: –– | W17: ––
A18: Buildings | B18: Install more heat pumps | C18: TWh (heat output) | D18: 1601.7225 | E18: =D18/Fig2Fig3Context!F9 -> 0.14494928 | F18: 3 | G18: =AVERAGE(M18:P18) -> 5048.4188 | H18: =MAX(M18:P18) -> 6001.991 | I18: =MIN(M18:P18) -> 4478.144 | J18: =AVERAGE(Q18:T18) -> 0.3802824 | K18: =MAX(Q18:T18) -> 0.61266378 | L18: =MIN(Q18:T18) -> 0.25584507 | M18: 4590.725 | N18: 5122.815 | O18: 4478.144 | P18: 6001.991 | Q18: =M18/Fig2Fig3Context!F$44 -> 0.30392326 | R18: =N18/Fig2Fig3Context!G$44 -> 0.3486975 | S18: =O18/Fig2Fig3Context!H$44 -> 0.25584507 | T18: =P18/Fig2Fig3Context!I$44 -> 0.61266378 | U18: –– | V18: –– | W18: ––
A19: Buildings | B19: Deploy more clean stoves | C19: Millions | D19: 348.57777 | E19: =D19/Fig2Fig3Context!F10 -> 0.3843376 | F19: 4 | G19: =U19 -> 660.191 | H19: –– | I19: –– | J19: =U19/Fig2Fig3Context!F10 -> 0.72791854 | K19: –– | L19: –– | M19: –– | N19: –– | O19: –– | P19: –– | Q19: –– | R19: –– | S19: –– | T19: –– | U19: 660.191 | V19: –– | W19: ––
A20: Industry | B20: Deploy direct air capture | C20: TWh (input) | D20: 0 | E20: =D20/Fig2Fig3Context!$F$6 -> 0 | F20: Negligible | G20: =AVERAGE(M20:P20) -> 1541.063 | H20: =MAX(M20:P20) -> 1541.063 | I20: =MIN(M20:P20) -> 1541.063 | J20: =AVERAGE(Q20:T20) -> 0.035486066 | K20: =MAX(Q20:T20) -> 0.0447909 | L20: =MIN(Q20:T20) -> 0.02501017 | M20: 1541.063 | N20: 1541.063 | O20: 1541.063 | P20: 1541.063 | Q20: =M20/Fig2Fig3Context!F$41 -> 0.035156858 | R20: =N20/Fig2Fig3Context!G$41 -> 0.036986338 | S20: =O20/Fig2Fig3Context!H$41 -> 0.02501017 | T20: =P20/Fig2Fig3Context!I$41 -> 0.0447909 | U20: –– | V20: –– | W20: ––
A21: Industry | B21: Produce clean hydrogen | C21: Mt | D21: 0.6 | E21: =D21/Fig2Fig3Context!F7 -> 0.006185567 | F21: 2 | G21: =AVERAGE(M21:P21) -> 152.44113 | H21: =MAX(M21:P21) -> 155.32303 | I21: =MIN(M21:P21) -> 150.37658 | J21: =AVERAGE(Q22:T23) -> 0.5081371 | K21: =MAX(Q22:T23) -> 0.77661516 | L21: =MIN(Q22:T23) -> 0.25062763 | M21: 151.6769 | N21: 155.32303 | O21: 150.37658 | P21: 152.38801 | Q21: –– | R21: –– | S21: –– | T21: –– | U21: –– | V21: –– | W21: ––
A22: Industry | B22: … low demand for hydrogen | C22: Mt | D22: –– | E22: –– | F22: –– | G22: –– | H22: –– | I22: –– | J22: –– | K22: –– | L22: –– | M22: –– | N22: –– | O22: –– | P22: –– | Q22: =M21/Fig2Fig3Context!$F34 -> 0.75838448 | R22: =N21/Fig2Fig3Context!$F34 -> 0.77661516 | S22: =O21/Fig2Fig3Context!$F34 -> 0.7518829 | T22: =P21/Fig2Fig3Context!$F34 -> 0.76194006 | U22: –– | V22: –– | W22: ––
A23: Industry | B23: … high demand for hydrogen | C23: Mt | D23: –– | E23: –– | F23: –– | G23: –– | H23: –– | I23: –– | J23: –– | K23: –– | L23: –– | M23: –– | N23: –– | O23: –– | P23: –– | Q23: =M21/Fig2Fig3Context!$F35 -> 0.25279483 | R23: =N21/Fig2Fig3Context!$F35 -> 0.25887172 | S23: =O21/Fig2Fig3Context!$F35 -> 0.25062763 | T23: =P21/Fig2Fig3Context!$F35 -> 0.25398002 | U23: –– | V23: –– | W23: ––
A24: Industry | B24: Decarbonise steelmaking | C24: Gt (output) | D24: 0 | E24: =D24/Fig2Fig3Context!$F$11 -> 0 | F24: Negligible | G24: =AVERAGE(M24:P24) -> 1.2916301 | H24: =MAX(M24:P24) -> 1.3525723 | I24: =MIN(M24:P24) -> 1.2147388 | J24: =AVERAGE(Q24:T24) -> 0.39400737 | K24: =MAX(Q24:T24) -> 0.44650019 | L24: =MIN(Q24:T24) -> 0.28312224 | M24: =AVERAGE(M25:M26) -> 1.3088192 | N24: =AVERAGE(N25:N26) -> 1.3525723 | O24: =AVERAGE(O25:O26) -> 1.2147388 | P24: =AVERAGE(P25:P26) -> 1.2903902 | Q24: =M24/Fig2Fig3Context!F$45 -> 0.41185685 | R24: =N24/Fig2Fig3Context!G$45 -> 0.43455022 | S24: =O24/Fig2Fig3Context!H$45 -> 0.28312224 | T24: =P24/Fig2Fig3Context!I$45 -> 0.44650019 | U24: –– | V24: –– | W24: ––
A25: Industry | B25: … with hydrogen-DRI | C25: Gt (output) | D25: 0 | E25: =D25/Fig2Fig3Context!$F$11 -> 0 | F25: Negligible | G25: –– | H25: –– | I25: –– | J25: –– | K25: –– | L25: –– | M25: 1.15718 | N25: 1.2302431 | O25: 1.0610698 | P25: 1.1470524 | Q25: =M25/Fig2Fig3Context!F$45 -> 0.36413931 | R25: =N25/Fig2Fig3Context!G$45 -> 0.39524867 | S25: =O25/Fig2Fig3Context!H$45 -> 0.24730623 | T25: =P25/Fig2Fig3Context!I$45 -> 0.39690249 | U25: –– | V25: –– | W25: ––
A26: Industry | B26: … with CCS | C26: Gt (output) | D26: 0 | E26: =D26/Fig2Fig3Context!$F$11 -> 0 | F26: Negligible | G26: –– | H26: –– | I26: –– | J26: –– | K26: –– | L26: –– | M26: 1.4604584 | N26: 1.4749015 | O26: 1.3684077 | P26: 1.4337281 | Q26: =M26/Fig2Fig3Context!F$45 -> 0.45957438 | R26: =N26/Fig2Fig3Context!G$45 -> 0.47385176 | S26: =O26/Fig2Fig3Context!H$45 -> 0.31893826 | T26: =P26/Fig2Fig3Context!I$45 -> 0.49609789 | U26: –– | V26: –– | W26: ––
A27: Industry | B27: Decarbonise cement production | C27: Gt (output) | D27: 0 | E27: =D27/Fig2Fig3Context!$F$12 -> 0 | F27: Negligible | G27: =AVERAGE(M27:P27) -> 4.953594 | H27: =MAX(M27:P27) -> 5.0371031 | I27: =MIN(M27:P27) -> 4.8648678 | J27: =AVERAGE(Q27:T27) -> 0.92926592 | K27: =MAX(Q27:T27) -> 1.0586838 | L27: =MIN(Q27:T27) -> 0.63696144 | M27: 4.9316928 | N27: 4.8648678 | O27: 4.9807125 | P27: 5.0371031 | Q27: =M27/Fig2Fig3Context!F46 -> 1.0402315 | R27: =N27/Fig2Fig3Context!G46 -> 1.0586838 | S27: =O27/Fig2Fig3Context!H46 -> 0.63696144 | T27: =P27/Fig2Fig3Context!I46 -> 0.98118689 | U27: –– | V27: –– | W27: ––
A28: Industry | B28: Reduce methane from oil and gas | C28: GtCO2e (cum.) | D28: –– | E28: –– | F28: –– | G28: =AVERAGE(M28:P28) -> -30 | H28: =MAX(M28:P28) -> -30 | I28: =MIN(M28:P28) -> -30 | J28: =AVERAGE(Q28:T28) -> -0.43920106 | K28: =MAX(Q28:T28) -> -0.39580845 | L28: =MIN(Q28:T28) -> -0.47411805 | M28: -30 | N28: -30 | O28: -30 | P28: -30 | Q28: =M28/Fig2Fig3Context!F47 -> -0.4324264 | R28: =N28/Fig2Fig3Context!G47 -> -0.47411805 | S28: =O28/Fig2Fig3Context!H47 -> -0.39580845 | T28: =P28/Fig2Fig3Context!I47 -> -0.45445133 | U28: –– | V28: –– | W28: ––
A29: Industry | B29: Reduce refrigerant pollution | C29: GtCO2e (cum.) | D29: –– | E29: –– | F29: –– | G29: =U29 -> -30 | H29: –– | I29: –– | J29: =U29/Fig2Fig3Context!F24 -> -0.65217391 | K29: –– | L29: –– | M29: –– | N29: –– | O29: –– | P29: –– | Q29: –– | R29: –– | S29: –– | T29: –– | U29: -30 | V29: –– | W29: ––
A30: Land use | B30: Reforest the tropics | C30: Mha | D30: 66.3 | E30: =D30/Fig2Fig3Context!F17 -> 0.044214738 | F30: 12 | G30: =U30 -> 103.838 | H30: =V30 -> 130.5969 | I30: =W30 -> 86.04148 | J30: =U30/Fig2Fig3Context!$F$29 -> 0.065866159 | K30: =V30/Fig2Fig3Context!$F$29 -> 0.082839772 | L30: =W30/Fig2Fig3Context!$F$29 -> 0.054577533 | M30: –– | N30: –– | O30: –– | P30: –– | Q30: –– | R30: –– | S30: –– | T30: –– | U30: 103.838 | V30: 130.5969 | W30: 86.04148
A31: Land use | B31: Reforest the temperate zone | C31: Mha | D31: 43.5 | E31: =D31/Fig2Fig3Context!F18 -> 0.06744186 | F31: 12 | G31: =U31 -> 143.0462 | H31: =V31 -> 184.2031 | I31: =W31 -> 117.0497 | J31: =U31/Fig2Fig3Context!$F$30 -> 0.22960867 | K31: =V31/Fig2Fig3Context!$F$30 -> 0.29567111 | L31: =W31/Fig2Fig3Context!$F$30 -> 0.18788074 | M31: –– | N31: –– | O31: –– | P31: –– | Q31: –– | R31: –– | S31: –– | T31: –– | U31: 143.0462 | V31: 184.2031 | W31: 117.0497
A32: Land use | B32: Add trees to tropical pasture | C32: Mha | D32: –– | E32: –– | F32: –– | G32: =U32 -> 129.0331 | H32: =V32 -> 216.036 | I32: =W32 -> 92.82798 | J32: =U32/Fig2Fig3Context!$F$27 -> 0.29527025 | K32: =V32/Fig2Fig3Context!$F$27 -> 0.49436156 | L32: =W32/Fig2Fig3Context!$F$27 -> 0.21242101 | M32: –– | N32: –– | O32: –– | P32: –– | Q32: –– | R32: –– | S32: –– | T32: –– | U32: 129.0331 | V32: 216.036 | W32: 92.82798
A33: Land use | B33: Add trees to temperate pasture | C33: Mha | D33: –– | E33: –– | F33: –– | G33: =U33 -> 175.2986 | H33: =V33 -> 277.1797 | I33: =W33 -> 128.1203 | J33: =U33/Fig2Fig3Context!$F$28 -> 0.63861056 | K33: =V33/Fig2Fig3Context!$F$28 -> 1.0097621 | L33: =W33/Fig2Fig3Context!$F$28 -> 0.46674062 | M33: –– | N33: –– | O33: –– | P33: –– | Q33: –– | R33: –– | S33: –– | T33: –– | U33: 175.2986 | V33: 277.1797 | W33: 128.1203
A34: Land use | B34: Add trees to tropical cropland | C34: Mha | D34: –– | E34: –– | F34: –– | G34: =U34 -> 152.0357 | H34: =V34 -> 169.082 | I34: =W34 -> 137.802 | J34: =U34/Fig2Fig3Context!$F$25 -> 0.35563906 | K34: =V34/Fig2Fig3Context!$F$25 -> 0.39551345 | L34: =W34/Fig2Fig3Context!$F$25 -> 0.32234386 | M34: –– | N34: –– | O34: –– | P34: –– | Q34: –– | R34: –– | S34: –– | T34: –– | U34: 152.0357 | V34: 169.082 | W34: 137.802
A35: Land use | B35: Enhance weathering in cropland | C35: Mha | D35: 0 | E35: =D35/Fig2Fig3Context!F19 -> 0 | F35: Negligible | G35: =U35 -> 320 | H35: –– | I35: –– | J35: =U35/Fig2Fig3Context!$F$31 -> 0.19710502 | K35: –– | L35: –– | M35: –– | N35: –– | O35: –– | P35: –– | Q35: –– | R35: –– | S35: –– | T35: –– | U35: 320 | V35: –– | W35: ––
A36: Land use | B36: Add trees to temperate cropland | C36: Mha | D36: –– | E36: –– | F36: –– | G36: =U36 -> 338.5561 | H36: =V36 -> 541.3706 | I36: =W36 -> 246.6356 | J36: =U36/Fig2Fig3Context!$F$26 -> 0.80036903 | K36: =V36/Fig2Fig3Context!$F$26 -> 1.2798359 | L36: =W36/Fig2Fig3Context!$F$26 -> 0.58306288 | M36: –– | N36: –– | O36: –– | P36: –– | Q36: –– | R36: –– | S36: –– | T36: –– | U36: 338.5561 | V36: 541.3706 | W36: 246.6356
A37: Land use | B37: Manage soil carbon | C37: Mha | D37: 180 | E37: =D37/Fig2Fig3Context!F19 -> 0.11087157 | F37: 13 | G37: =U37 -> 904 | H37: =V37 -> 1371 | I37: =W37 -> 675 | J37: =U37/Fig2Fig3Context!$F$31 -> 0.55682168 | K37: =V37/Fig2Fig3Context!$F$31 -> 0.84447182 | L37: =W37/Fig2Fig3Context!$F$31 -> 0.4157684 | M37: –– | N37: –– | O37: –– | P37: –– | Q37: –– | R37: –– | S37: –– | T37: –– | U37: 904 | V37: 1371 | W37: 675
A38: Land use | B38: Prevent tropical forest loss | C38: Mha/year | D38: 12.85 | E38: –– | F38: 12 | G38: =U38 -> -4.978338 | H38: =V38 -> -4.493484 | I38: =W38 -> -5.577543 | J38: =U38/$D$38 -> -0.3874193 | K38: =V38/$D$38 -> -0.34968747 | L38: =W38/$D$38 -> -0.43405004 | M38: –– | N38: –– | O38: –– | P38: –– | Q38: –– | R38: –– | S38: –– | T38: –– | U38: -4.978338 | V38: -4.493484 | W38: -5.577543
A39: Land use | B39: Rewet drained peatlands | C39: Mha | D39: 20.3 | E39: –– | F39: 14 | G39: =U39 -> 18.04216 | H39: =V39 -> 45.23379 | I39: =W39 -> 11.19254 | J39: =U39/$D$39 -> 0.88877635 | K39: =V39/$D$39 -> 2.2282655 | L39: =W39/$D$39 -> 0.55135665 | M39: –– | N39: –– | O39: –– | P39: –– | Q39: –– | R39: –– | S39: –– | T39: –– | U39: 18.04216 | V39: 45.23379 | W39: 11.19254
A40: Land use | B40: ...and phase-out drainage | C40: Mha/year | D40: 0.57 | E40: –– | F40: 15 | G40: =U40 -> -0.5472178 | H40: =V40 -> -0.3514677 | I40: =W40 -> -1.211561 | J40: =U40/$D$40 -> -0.96003123 | K40: =V40/$D$40 -> -0.61661 | L40: =W40/$D$40 -> -2.1255456 | M40: –– | N40: –– | O40: –– | P40: –– | Q40: –– | R40: –– | S40: –– | T40: –– | U40: -0.5472178 | V40: -0.3514677 | W40: -1.211561
...

Sheet Fig2Fig3Context
B3: Contextual elements to calculate present day shares
C5: Variable | D5: Year | E5: Unit | F5: Value | G5: Source
C6: Global electricity generation | D6: 2024 | E6: TWh | F6: 30914.83 | G6: 1
C7: Global hydrogen demand | D7: 2023 | E7: Mt | F7: 97 | G7: 2
C8: Global passenger-km travelled by land (domestic only) | D8: 2020 | E8: Trillion p-km | F8: 69.48596 | G8: 3
C9: Global useful energy for space and water heating | D9: 2020 | E9: TWh | F9: 11050.227 | G9: 3
C10: Global households reliant on cookstoves | D10: 2020 | E10: Million | F10: 906.95725 | G10: 4
C11: Global steel production | D11: 2020 | E11: Gt | F11: 2.1795505 | G11: 3
C12: Global cement production | D12: 2020 | E12: Gt | F12: 4.3625501 | G12: 3
C13: Tropical cropland area | D13: 1991-2020 | E13: Mha | F13: 369 | G13: 5
C14: Temperate cropland area | D14: 1991-2020 | E14: Mha | F14: 421 | G14: 5
C15: Tropical pasture area | D15: 1991-2020 | E15: Mha | F15: 417 | G15: 5
C16: Temperate pasture area | D16: 1991-2020 | E16: Mha | F16: 285 | G16: 5
C17: Tropical forest area | D17: 1991-2020 | E17: Mha | F17: 1499.5 | G17: 5
C18: Temperate forest area | D18: 1991-2020 | E18: Mha | F18: 645 | G18: 5
C19: Global cropland area | D19: 1991-2020 | E19: Mha | F19: 1623.5 | G19: 5
B21: Contextual elements to calculate 2050 shares (scenario independent)
C23: Variable | D23: Year | E23: Unit | F23: Value | G23: Source
C24: Global cumulative HFC emissions | D24: 2050 | E24: GtCO2e | F24: 46 | G24: 6
C25: Tropical cropland area | D25: 2050 | E25: Mha | F25: 427.5 | G25: 5
C26: Temperate cropland area | D26: 2050 | E26: Mha | F26: 423 | G26: 5
C27: Tropical pasture area | D27: 2050 | E27: Mha | F27: 437 | G27: 5
C28: Temperate pasture area | D28: 2050 | E28: Mha | F28: 274.5 | G28: 5
C29: Tropical forest area | D29: 2050 | E29: Mha | F29: 1576.5 | G29: 5
C30: Temperate forest area | D30: 2050 | E30: Mha | F30: 623 | G30: 5
C31: Global cropland area | D31: 2050 | E31: Mha | F31: 1623.5 | G31: 5
C32: Calories from meat in medium/high meat-eating regions | D32: 2050 | E32: kcal/cap/day | F32: 398.94545 | G32: 7
C33: Global food loss and waste | D33: 2050 | E33: Gt | F33: 2.7195794 | G33: 8
C34: Global hydrogen demand (low) | D34: 2050 | E34: Mt | F34: 200 | G34: 9
C35: Global hydrogen demand (high) | D35: 2050 | E35: Mt | F35: 600 | G35: 9
B37: Contextual elements to calculate 2050 shares from baseline scenarios
F39: Values
C40: Variable | D40: Year | E40: Unit | F40: IEA6 | G40: IEA4 | H40: RCP8 | I40: RCP6
C41: Global electricity generation | D41: 2050 | E41: TWh | F41: 43833.923 | G41: 41665.736 | H41: 61617.455 | I41: 34405.716
C42: Global passenger-km travelled by land (domestic only) | D42: 2050 | E42: TWh | F42: 104.75817 | G42: 104.75817 | H42: 123.25861 | I42: 111.30212
C43: Global passenger-km travelled by air | D43: 2050 | E43: Trillion p-km | F43: 11.62 | G43: 11.62 | H43: 25.9 | I43: 19.24
C44: Global useful energy for space and water heating | D44: 2050 | E44: TWh | F44: 15104.882 | G44: 14691.287 | H44: 17503.343 | I44: 9796.5494
C45: Global demand for steel from all sources | D45: 2050 | E45: Gt | F45: 3.1778498 | G45: 3.1125799 | H45: 4.2905098 | I45: 2.8900105
C46: Global demand for cement from all sources | D46: 2050 | E46: Gt | F46: 4.7409568 | G46: 4.5952036 | H46: 7.8194881 | I46: 5.1336836
C47: Global cumulative methane emissions from oil and gas | D47: 2020-2050 | E47: GtCO2e | F47: 69.375967 | G47: 63.27538 | H47: 75.794238 | I47: 66.01367
...

Sheet Fig4
A1: Figure | B1: Sector | C1: Strategy | D1: AR6 Variable | E1: Model Family | F1: n | G1: Mean | H1: SD | I1: P25 | J1: P50 | K1: P75 | L1: Nrml. Mean | M1: Nrml. SD | N1: Nrml. P25 | O1: Nrml. P50 | P1: Nrml. P75
A2: 4a | B2: All | C2: Electricity | D2: Emissions|CO2|Energy|Supply | E2: All | F2: 367 | G2: 7.6488268 | H2: 2.5502912 | I2: 5.93737 | J2: 7.0306716 | K2: 9.0384241 | L2: 7.663341 | M2: 1.6907801 | N2: 6.325099 | O2: 7.4827803 | P2: 8.6032406
A3: 4a | B3: All | C3: Industry | D3: Emissions|Industry|All | E3: All | F3: 249 | G3: 5.166148 | H3: 1.5550225 | I3: 4.2044473 | J3: 5.020005 | K3: 6.3726425 | L3: 5.3951896 | M3: 1.1271916 | N3: 4.8534002 | O3: 5.2629147 | P3: 5.8999752
A4: 4a | B4: All | C4: Transport | D4: Emissions|Transport|All | E4: All | F4: 291 | G4: 2.3669671 | H4: 0.93213039 | I4: 1.6446036 | J4: 2.2559947 | K4: 3.0482478 | L4: 2.4846823 | M4: 0.84148809 | N4: 1.7620197 | O4: 2.4544616 | P4: 3.1264516
A5: 4a | B5: All | C5: Land | D5: Emissions|Land|All | E5: All | F5: 325 | G5: 2.2108928 | H5: 1.3749503 | I5: 1.1167643 | J5: 2.0928505 | K5: 3.4440979 | L5: 2.2939908 | M5: 1.4566653 | N5: 1.2824408 | O5: 2.3119915 | P5: 3.126423
A6: 4a | B6: All | C6: Buildings | D6: Emissions|CO2|Energy|Demand|Residential and Commercial | E6: All | F6: 331 | G6: 1.0914334 | H6: 0.37738115 | I6: 0.76901468 | J6: 1.0859226 | K6: 1.3849879 | L6: 1.0953007 | M6: 0.31577425 | N6: 0.87432515 | O6: 1.0894538 | P6: 1.313043
A7: 4b | B7: Electricity | C7: Wind | D7: Secondary Energy|Electricity|Wind | E7: All | F7: 376 | G7: 3.30422 | H7: 2.5523816 | I7: 1.4877934 | J7: 2.6798547 | K7: 4.6352429 | L7: 3.308991 | M7: 2.3990359 | N7: 1.5431393 | O7: 2.8371887 | P7: 4.7329457
A8: 4b | B8: Electricity | C8: Solar | D8: Secondary Energy|Electricity|Solar | E8: All | F8: 376 | G8: 3.0801445 | H8: 2.0868043 | I8: 1.306462 | J8: 2.8841668 | K8: 4.4807017 | L8: 3.0243353 | M8: 1.8145298 | N8: 1.4947478 | O8: 2.940161 | P8: 4.3557807
A9: 4b | B9: Electricity | C9: Nuclear | D9: Secondary Energy|Electricity|Nuclear | E9: All | F9: 377 | G9: 1.1385037 | H9: 1.365425 | I9: 0.11367729 | J9: 0.52151913 | K9: 1.9258309 | L9: 1.1790361 | M9: 1.4451677 | N9: 0.13706437 | O9: 0.49416183 | P9: 1.8891043
A10: 4b | B10: Electricity | C10: BECCS | D10: Secondary Energy|Electricity|Biomass|w/ CCS | E10: All | F10: 364 | G10: 0.79771277 | H10: 0.98407569 | I10: 0.15109628 | J10: 0.3804383 | K10: 1.0959192 | L10: 0.84249929 | M10: 1.0508902 | N10: 0.15581871 | O10: 0.41024612 | P10: 1.1166592
A11: 4b | B11: Electricity | C11: Gas CCS | D11: Secondary Energy|Electricity|Gas|w/ CCS | E11: All | F11: 365 | G11: 0.41277677 | H11: 0.56426007 | I11: 0.054019746 | J11: 0.15861371 | K11: 0.68472597 | L11: 0.47090239 | M11: 0.76778811 | N11: 0.058237837 | O11: 0.15787681 | P11: 0.67500681
A12: 4b | B12: Electricity | C12: Coal CCS | D12: Secondary Energy|Electricity|Coal|w/ CCS | E12: All | F12: 365 | G12: 0.10729233 | H12: 0.34235074 | I12: -9.7159069e-06 | J12: 0.02412128 | K12: 0.14585298 | L12: 0.11435307 | M12: 0.42449452 | N12: -8.0114018e-06 | O12: 0.022698526 | P12: 0.14962067
A13: –– | B13: Industry | C13: Green H2 | D13: Secondary Energy|Hydrogen|Electricity | E13: All | F13: 195 | G13: 0.57612465 | H13: 0.55563358 | I13: 0.16810219 | J13: 0.50910295 | K13: 0.80177061 | L13: 0.57523415 | M13: 0.5819033 | N13: 0.19793734 | O13: 0.53410533 | P13: 0.77567953
... A36: –– | B36: Electricity | C36: Coal CCS | D36: Secondary Energy|Electricity|Coal|w/ CCS | E36: AIM | F36: 11 | G36: 0.35520908 | H36: 0.64618264 | I36: -0.23615341 | J36: 0.10837123 | K36: 0.94388175 | L36: -0.36423269 | M36: 0.68499302 | N36: -0.36423269 | O36: 0.22059326 | P36: 0.98614329
A37: –– | B37: Industry | C37: Green H2 | D37: Secondary Energy|Hydrogen|Electricity | E37: AIM | F37: 0 | G37: NA | H37: NA | I37: NA | J37: NA | K37: NA | L37: NA | M37: NA | N37: NA | O37: NA | P37: NA
A38: –– | B38: Industry | C38: Blue H2 | D38: Secondary Energy|Hydrogen|Fossil|w/ CCS | E38: AIM | F38: 0 | G38: NA | H38: NA | I38: NA | J38: NA | K38: NA | L38: NA | M38: NA | N38: NA | O38: NA | P38: NA
A39: –– | B39: Industry | C39: Clean hydrogen | D39: Secondary Energy|Hydrogen|Clean | E39: AIM | F39: 0 | G39: NA | H39: NA | I39: NA | J39: NA | K39: NA | L39: NA | M39: NA | N39: NA | O39: NA | P39: NA
A40: –– | B40: Industry | C40: Methane reduction | D40: Emissions|CH4|Energy|Supply | E40: AIM | F40: 9 | G40: 0.46951967 | H40: 0.56048004 | I40: 0.1805505 | J40: 0.200607 | K40: 0.489153 | L40: 0.29986012 | M40: 0.38032454 | N40: 0.29986012 | O40: 0.32909626 | P40: 0.63610537
A41: –– | B41: Industry | C41: Industry CCS | D41: Carbon Sequestration|CCS|Fossil|Energy|Demand|Industry | E41: AIM | F41: 8 | G41: 0.22727066 | H41: 0.043431352 | I41: 0.18523076 | J41: 0.24478388 | K41: 0.26092316 | L41: 0.31445492 | M41: 0.065455891 | N41: 0.31445492 | O41: 0.3511628 | P41: 0.38738705
A42: –– | B42: Industry | C42: HFC reduction | D42: Emissions|HFC | E42: AIM | F42: 9 | G42: 0.19376505 | H42: 0.31601727 | I42: 0.00030576 | J42: 0.000360815 | K42: 0.29146247 | L42: 0.00053254726 | M42: 0.33923096 | N42: 0.00053254726 | O42: 0.00054937877 | P42: 0.27047182
A43: –– | B43: Industry | C43: Direct air capture | D43: Carbon Sequestration|Direct Air Capture | E43: AIM | F43: 0 | G43: NA | H43: NA | I43: NA | J43: NA | K43: NA | L43: NA | M43: NA | N43: NA | O43: NA | P43: NA
A44: –– | B44: Transport | C44: Electric vehicles | D44: Final Energy|Transportation|Electricity | E44: AIM | F44: 13 | G44: 1.081798 | H44: 0.64976529 | I44: 0.90142865 | J44: 1.0384228 | K44: 1.5143103 | L44: 0.83900006 | M44: 0.90076843 | N44: 0.83900006 | O44: 1.4243785 | P44: 2.1969768
A45: –– | B45: Transport | C45: Freight transport | D45: Emissions|CO2|Energy|Demand|Transportation|Freight | E45: AIM | F45: 0 | G45: NA | H45: NA | I45: NA | J45: NA | K45: NA | L45: NA | M45: NA | N45: NA | O45: NA | P45: NA
A46: –– | B46: Transport | C46: Biofuels | D46: Final Energy|Transportation|Liquids|Bioenergy | E46: AIM | F46: 8 | G46: 0.27145774 | H46: 0.11164644 | I46: 0.20206247 | J46: 0.26840909 | K46: 0.30618187 | L46: 0.28389414 | M46: 0.13756083 | N46: 0.28389414 | O46: 0.36551777 | P46: 0.46842235
A47: –– | B47: Land | C47: Afforestation | D47: Carbon Sequestration|Land Use|Afforestation | E47: AIM | F47: 1 | G47: 0.84726475 | H47: NA | I47: NA | J47: 0.84726475 | K47: NA | L47: NA | M47: NA | N47: NA | O47: 0.79969434 | P47: NA
A48: –– | B48: Land | C48: Diet change | D48: Food Demand|Livestock | E48: AIM | F48: 10 | G48: 0.16884751 | H48: 0.067223491 | I48: 0.12678339 | J48: 0.17099562 | K48: 0.21092572 | L48: 0.1119858 | M48: 0.11408956 | N48: 0.1119858 | O48: 0.30683525 | P48: 0.32183494
A49: –– | B49: Land | C49: Enhanced weathering | D49: Carbon Sequestration|Enhanced Weathering | E49: AIM | F49: 0 | G49: NA | H49: NA | I49: NA | J49: NA | K49: NA | L49: NA | M49: NA | N49: NA | O49: NA | P49: NA
A50: –– | B50: All | C50: Electricity | D50: Emissions|CO2|Energy|Supply | E50: GCAM | F50: 15 | G50: 6.6808978 | H50: 0.83020065 | I50: 6.5320314 | J50: 6.6389874 | K50: 7.3617818 | L50: 9.2068066 | M50: 0.8850515 | N50: 9.2068066 | O50: 9.7280389 | P50: 9.8967381
A51: –– | B51: All | C51: Industry | D51: Emissions|Industry|All | E51: GCAM | F51: 15 | G51: 4.2989445 | H51: 0.72016447 | I51: 4.0295056 | J51: 4.1137857 | K51: 4.6781794 | L51: 5.8148902 | M51: 0.31517683 | N51: 5.8148902 | O51: 6.0208515 | P51: 6.1351984
A52: –– | B52: All | C52: Transport | D52: Emissions|Transport|All | E52: GCAM | F52: 15 | G52: 1.550272 | H52: 0.53867519 | I52: 1.2652128 | J52: 1.3441536 | K52: 2.0825803 | L52: 1.8451748 | M52: 0.4380316 | N52: 1.8451748 | O52: 2.02343 | P52: 2.447474
A53: –– | B53: All | C53: Land | D53: Emissions|Land|All | E53: GCAM | F53: 15 | G53: 1.0739984 | H53: 1.278595 | I53: 0.51721579 | J53: 0.62881856 | K53: 0.80083747 | L53: 0.87401913 | M53: 1.1630489 | N53: 0.87401913 | O53: 0.93570074 | P53: 1.0531862
A54: –– | B54: All | C54: Buildings | D54: Emissions|CO2|Energy|Demand|Residential and Commercial | E54: GCAM | F54: 15 | G54: 0.76623612 | H54: 0.1389274 | I54: 0.71156095 | J54: 0.7288237 | K54: 0.91824029 | L54: 1.059962 | M54: 0.10165027 | N54: 1.059962 | O54: 1.0690424 | P54: 1.1413918
A55: –– | B55: Electricity | C55: Wind | D55: Secondary Energy|Electricity|Wind | E55: GCAM | F55: 15 | G55: 2.5642659 | H55: 1.4939336 | I55: 1.6126876 | J55: 1.9019908 | K55: 2.6419051 | L55: 2.4948915 | M55: 1.4253726 | N55: 2.4948915 | O55: 2.8127216 | P55: 3.2845369
A56: –– | B56: Electricity | C56: Solar | D56: Secondary Energy|Electricity|Solar | E56: GCAM | F56: 15 | G56: 2.3731536 | H56: 1.6993506 | I56: 1.3481593 | J56: 1.5778424 | K56: 2.2873324 | L56: 2.0732304 | M56: 1.7175375 | N56: 2.0732304 | O56: 2.3585873 | P56: 2.8437178
A57: –– | B57: Electricity | C57: Nuclear | D57: Secondary Energy|Electricity|Nuclear | E57: GCAM | F57: 15 | G57: 2.6137446 | H57: 1.1999477 | I57: 1.8956267 | J57: 2.685083 | K57: 3.5267574 | L57: 3.7401084 | M57: 1.5547186 | N57: 3.7401084 | O57: 4.0691656 | P57: 4.6424095
A58: –– | B58: Electricity | C58: BECCS | D58: Secondary Energy|Electricity|Biomass|w/ CCS | E58: GCAM | F58: 15 | G58: 2.0434194 | H58: 0.70935409 | I58: 1.5753737 | J58: 2.2072138 | K58: 2.5864561 | L58: 3.0555604 | M58: 0.99498717 | N58: 3.0555604 | O58: 3.3097974 | P58: 3.4958911
A59: –– | B59: Electricity | C59: Gas CCS | D59: Secondary Energy|Electricity|Gas|w/ CCS | E59: GCAM | F59: 15 | G59: 0.69068565 | H59: 0.39670059 | I59: 0.75338318 | J59: 0.81167691 | K59: 0.97479841 | L59: 0.95015898 | M59: 0.60498035 | N59: 0.95015898 | O59: 1.392091 | P59: 1.4847675
A60: –– | B60: Electricity | C60: Coal CCS | D60: Secondary Energy|Electricity|Coal|w/ CCS | E60: GCAM | F60: 15 | G60: 0.47288626 | H60: 0.64910246 | I60: -0.16842403 | J60: 0.82689781 | K60: 1.1398884 | L60: -0.23030202 | M60: 1.025777 | N60: -0.23030202 | O60: 1.235153 | P60: 1.762954
A61: –– | B61: Industry | C61: Green H2 | D61: Secondary Energy|Hydrogen|Electricity | E61: GCAM | F61: 3 | G61: 0.035619516 | H61: 0.010602606 | I61: 0.022759007 | J61: 0.037197454 | K61: 0.046614756 | L61: 0.03338303 | M61: 0.0045227486 | N61: 0.03338303 | O61: 0.039662233 | P61: 0.042909569
... A66: –– | B66: Industry | C66: HFC reduction | D66: Emissions|HFC | E66: GCAM | F66: 15 | G66: 0.10532463 | H66: 0.053805015 | I66: 0.069101829 | J66: 0.091578036 | K66: 0.09187709 | L66: 0.097725398 | M66: 0.056168229 | N66: 0.097725398 | O66: 0.13700767 | P66: 0.15506805
...
